Workbook
Name Slicer_DayName: #N/A
Name Slicer_Month: #N/A
Name Slicer_Movie_Type: #N/A
Name Slicer_Profit___Loss: #N/A
Name Slicer_Runtime_Classification: #N/A
Name Slicer_Vote_Category: #N/A
Name Slicer_year1: #N/A

Sheet imdb_data
A1: id | B1: primaryTitle | C1: originalTitle | D1: isAdult | E1: runtimeMinutes | F1: Hour | G1: Minutes | H1: Runtime Classification | I1: Genres1 | J1: Genres2 | K1: Genres3 | L1: averageRating | M1: Movie Type | N1: numVotes | O1: Vote Category | P1: budget | Q1: gross | R1: Profit | S1: Profit & Loss | T1: release_date | U1: directors | V1: Release_Date | W1: Month | X1: Year | Y1: year1 | Z1: Day | AA1: day 1 | AB1: DayName
A2: tt0035423 | B2: Kate & Leopold | C2: Kate & Leopold | D2: 0 | E2: 118 | F2: =INT(E2/60) -> 1 | G2: =MOD(E2,60) -> 58 | H2: {=_xlfn.IFS(E2<=80,"Series",E2<=120,"TV Movie",E2>120,"Long Movie")} -> TV Movie | I2: Comedy | J2: Fantasy | K2: Romance | L2: 6.4 | M2: {=_xlfn.IFS(L2<=2,"Flop",L2<=5,"Average",L2<=7,"Hit",L2<=9,"Superhit",L2>9,"BlockBuster")} -> Hit | N2: 87925 | O2: {=_xlfn.IFS(N2<=100000,"Low",N2<=500000,"Median",N2<=1500000,"High",N2>1500000,"Very High")} -> Low | P2: 48000000 | Q2: 76019048 | R2: =Q2-P2 -> 28019048 | S2: =IF(R2>0,"Profit","Loss") -> Profit | T2: 37236 | U2: James Mangold | V2: 37236 | W2: =TEXT(V2,"MMMM") -> December | X2: =TEXT(V2,"YYYY") -> 2001 | Y2: =VALUE(X2) -> 2001 | Z2: =TEXT(V2,"d") -> 11 | AA2: =VALUE(Z2) -> 11 | AB2: =TEXT(V2,"dddd") -> Tuesday
A3: tt0065421 | B3: The Aristocats | C3: The AristoCats | D3: 0 | E3: 78 | F3: =INT(E3/60) -> 1 | G3: =MOD(E3,60) -> 18 | H3: {=_xlfn.IFS(E3<=80,"Series",E3<=120,"TV Movie",E3>120,"Long Movie")} -> Series | I3: Adventure | J3: Animation | K3: Comedy | L3: 7.1 | M3: {=_xlfn.IFS(L3<=2,"Flop",L3<=5,"Average",L3<=7,"Hit",L3<=9,"Superhit",L3>9,"BlockBuster")} -> Superhit | N3: 111758 | O3: {=_xlfn.IFS(N3<=100000,"Low",N3<=500000,"Median",N3<=1500000,"High",N3>1500000,"Very High")} -> Median | P3: 4000000 | Q3: 35459543 | R3: =Q3-P3 -> 31459543 | S3: =IF(R3>0,"Profit","Loss") -> Profit | T3: 25913 | U3: Wolfgang Reitherman | V3: 25913 | W3: =TEXT(V3,"MMMM") -> December | X3: =TEXT(V3,"YYYY") -> 1970 | Y3: =VALUE(X3) -> 1970 | Z3: =TEXT(V3,"d") -> 11 | AA3: =VALUE(Z3) -> 11 | AB3: =TEXT(V3,"dddd") -> Friday
A4: tt0065938 | B4: Kelly's Heroes | C4: Kelly's Heroes | D4: 0 | E4: 144 | F4: =INT(E4/60) -> 2 | G4: =MOD(E4,60) -> 24 | H4: {=_xlfn.IFS(E4<=80,"Series",E4<=120,"TV Movie",E4>120,"Long Movie")} -> Long Movie | I4: Adventure | J4: Comedy | K4: War | L4: 7.6 | M4: {=_xlfn.IFS(L4<=2,"Flop",L4<=5,"Average",L4<=7,"Hit",L4<=9,"Superhit",L4>9,"BlockBuster")} -> Superhit | N4: 52628 | O4: {=_xlfn.IFS(N4<=100000,"Low",N4<=500000,"Median",N4<=1500000,"High",N4>1500000,"Very High")} -> Low | P4: 4000000 | Q4: 5200000 | R4: =Q4-P4 -> 1200000 | S4: =IF(R4>0,"Profit","Loss") -> Profit | T4: 25569 | U4: Brian G. Hutton | V4: 25569 | W4: =TEXT(V4,"MMMM") -> January | X4: =TEXT(V4,"YYYY") -> 1970 | Y4: =VALUE(X4) -> 1970 | Z4: =TEXT(V4,"d") -> 1 | AA4: =VALUE(Z4) -> 1 | AB4: =TEXT(V4,"dddd") -> Thursday
A5: tt0066026 | B5: M*A*S*H | C5: M*A*S*H | D5: 0 | E5: 116 | F5: =INT(E5/60) -> 1 | G5: =MOD(E5,60) -> 56 | H5: {=_xlfn.IFS(E5<=80,"Series",E5<=120,"TV Movie",E5>120,"Long Movie")} -> TV Movie | I5: Comedy | J5: Drama | K5: War | L5: 7.4 | M5: {=_xlfn.IFS(L5<=2,"Flop",L5<=5,"Average",L5<=7,"Hit",L5<=9,"Superhit",L5>9,"BlockBuster")} -> Superhit | N5: 75784 | O5: {=_xlfn.IFS(N5<=100000,"Low",N5<=500000,"Median",N5<=1500000,"High",N5>1500000,"Very High")} -> Low | P5: 3500000 | Q5: 81600000 | R5: =Q5-P5 -> 78100000 | S5: =IF(R5>0,"Profit","Loss") -> Profit | T5: 25593 | U5: Robert Altman | V5: 25593 | W5: =TEXT(V5,"MMMM") -> January | X5: =TEXT(V5,"YYYY") -> 1970 | Y5: =VALUE(X5) -> 1970 | Z5: =TEXT(V5,"d") -> 25 | AA5: =VALUE(Z5) -> 25 | AB5: =TEXT(V5,"dddd") -> Sunday
A6: tt0066206 | B6: Patton | C6: Patton | D6: 0 | E6: 172 | F6: =INT(E6/60) -> 2 | G6: =MOD(E6,60) -> 52 | H6: {=_xlfn.IFS(E6<=80,"Series",E6<=120,"TV Movie",E6>120,"Long Movie")} -> Long Movie | I6: Biography | J6: Drama | K6: War | L6: 7.9 | M6: {=_xlfn.IFS(L6<=2,"Flop",L6<=5,"Average",L6<=7,"Hit",L6<=9,"Superhit",L6>9,"BlockBuster")} -> Superhit | N6: 106476 | O6: {=_xlfn.IFS(N6<=100000,"Low",N6<=500000,"Median",N6<=1500000,"High",N6>1500000,"Very High")} -> Median | P6: 12000000 | Q6: 61749765 | R6: =Q6-P6 -> 49749765 | S6: =IF(R6>0,"Profit","Loss") -> Profit | T6: 25603 | U6: Franklin J. Schaffner | V6: 25603 | W6: =TEXT(V6,"MMMM") -> February | X6: =TEXT(V6,"YYYY") -> 1970 | Y6: =VALUE(X6) -> 1970 | Z6: =TEXT(V6,"d") -> 4 | AA6: =VALUE(Z6) -> 4 | AB6: =TEXT(V6,"dddd") -> Wednesday
A7: tt0066434 | B7: THX 1138 | C7: THX 1138 | D7: 0 | E7: 86 | F7: =INT(E7/60) -> 1 | G7: =MOD(E7,60) -> 26 | H7: {=_xlfn.IFS(E7<=80,"Series",E7<=120,"TV Movie",E7>120,"Long Movie")} -> TV Movie | I7: Drama | J7: Sci-Fi | K7: Thriller | L7: 6.6 | M7: {=_xlfn.IFS(L7<=2,"Flop",L7<=5,"Average",L7<=7,"Hit",L7<=9,"Superhit",L7>9,"BlockBuster")} -> Hit | N7: 53906 | O7: {=_xlfn.IFS(N7<=100000,"Low",N7<=500000,"Median",N7<=1500000,"High",N7>1500000,"Very High")} -> Low | P7: 777000 | Q7: 2437000 | R7: =Q7-P7 -> 1660000 | S7: =IF(R7>0,"Profit","Loss") -> Profit | T7: 26003 | U7: George Lucas | V7: 26003 | W7: =TEXT(V7,"MMMM") -> March | X7: =TEXT(V7,"YYYY") -> 1971 | Y7: =VALUE(X7) -> 1971 | Z7: =TEXT(V7,"d") -> 11 | AA7: =VALUE(Z7) -> 11 | AB7: =TEXT(V7,"dddd") -> Thursday
A8: tt0066921 | B8: A Clockwork Orange | C8: A Clockwork Orange | D8: 0 | E8: 136 | F8: =INT(E8/60) -> 2 | G8: =MOD(E8,60) -> 16 | H8: {=_xlfn.IFS(E8<=80,"Series",E8<=120,"TV Movie",E8>120,"Long Movie")} -> Long Movie | I8: Crime | J8: Sci-Fi | K8: Unknown | L8: 8.3 | M8: {=_xlfn.IFS(L8<=2,"Flop",L8<=5,"Average",L8<=7,"Hit",L8<=9,"Superhit",L8>9,"BlockBuster")} -> Superhit | N8: 864440 | O8: {=_xlfn.IFS(N8<=100000,"Low",N8<=500000,"Median",N8<=1500000,"High",N8>1500000,"Very High")} -> High | P8: 2200000 | Q8: 26960374 | R8: =Q8-P8 -> 24760374 | S8: =IF(R8>0,"Profit","Loss") -> Profit | T8: 26286 | U8: Stanley Kubrick | V8: 26286 | W8: =TEXT(V8,"MMMM") -> December | X8: =TEXT(V8,"YYYY") -> 1971 | Y8: =VALUE(X8) -> 1971 | Z8: =TEXT(V8,"d") -> 19 | AA8: =VALUE(Z8) -> 19 | AB8: =TEXT(V8,"dddd") -> Sunday
A9: tt0066995 | B9: Diamonds Are Forever | C9: Diamonds Are Forever | D9: 0 | E9: 120 | F9: =INT(E9/60) -> 2 | G9: =MOD(E9,60) -> 0 | H9: {=_xlfn.IFS(E9<=80,"Series",E9<=120,"TV Movie",E9>120,"Long Movie")} -> TV Movie | I9: Action | J9: Adventure | K9: Thriller | L9: 6.5 | M9: {=_xlfn.IFS(L9<=2,"Flop",L9<=5,"Average",L9<=7,"Hit",L9<=9,"Superhit",L9>9,"BlockBuster")} -> Hit | N9: 112043 | O9: {=_xlfn.IFS(N9<=100000,"Low",N9<=500000,"Median",N9<=1500000,"High",N9>1500000,"Very High")} -> Median | P9: 7200000 | Q9: 43829933 | R9: =Q9-P9 -> 36629933 | S9: =IF(R9>0,"Profit","Loss") -> Profit | T9: 26281 | U9: Guy Hamilton | V9: 26281 | W9: =TEXT(V9,"MMMM") -> December | X9: =TEXT(V9,"YYYY") -> 1971 | Y9: =VALUE(X9) -> 1971 | Z9: =TEXT(V9,"d") -> 14 | AA9: =VALUE(Z9) -> 14 | AB9: =TEXT(V9,"dddd") -> Tuesday
A10: tt0066999 | B10: Dirty Harry | C10: Dirty Harry | D10: 0 | E10: 102 | F10: =INT(E10/60) -> 1 | G10: =MOD(E10,60) -> 42 | H10: {=_xlfn.IFS(E10<=80,"Series",E10<=120,"TV Movie",E10>120,"Long Movie")} -> TV Movie | I10: Action | J10: Crime | K10: Thriller | L10: 7.7 | M10: {=_xlfn.IFS(L10<=2,"Flop",L10<=5,"Average",L10<=7,"Hit",L10<=9,"Superhit",L10>9,"BlockBuster")} -> Superhit | N10: 165277 | O10: {=_xlfn.IFS(N10<=100000,"Low",N10<=500000,"Median",N10<=1500000,"High",N10>1500000,"Very High")} -> Median | P10: 4000000 | Q10: 35988495 | R10: =Q10-P10 -> 31988495 | S10: =IF(R10>0,"Profit","Loss") -> Profit | T10: 26288 | U10: Don Siegel, Clint Eastwood | V10: 26288 | W10: =TEXT(V10,"MMMM") -> December | X10: =TEXT(V10,"YYYY") -> 1971 | Y10: =VALUE(X10) -> 1971 | Z10: =TEXT(V10,"d") -> 21 | AA10: =VALUE(Z10) -> 21 | AB10: =TEXT(V10,"dddd") -> Tuesday
A11: tt0067116 | B11: The French Connection | C11: The French Connection | D11: 0 | E11: 104 | F11: =INT(E11/60) -> 1 | G11: =MOD(E11,60) -> 44 | H11: {=_xlfn.IFS(E11<=80,"Series",E11<=120,"TV Movie",E11>120,"Long Movie")} -> TV Movie | I11: Action | J11: Crime | K11: Drama | L11: 7.7 | M11: {=_xlfn.IFS(L11<=2,"Flop",L11<=5,"Average",L11<=7,"Hit",L11<=9,"Superhit",L11>9,"BlockBuster")} -> Superhit | N11: 131995 | O11: {=_xlfn.IFS(N11<=100000,"Low",N11<=500000,"Median",N11<=1500000,"High",N11>1500000,"Very High")} -> Median | P11: 1800000 | Q11: 51701871 | R11: =Q11-P11 -> 49901871 | S11: =IF(R11>0,"Profit","Loss") -> Profit | T11: 26213 | U11: William Friedkin | V11: 26213 | W11: =TEXT(V11,"MMMM") -> October | X11: =TEXT(V11,"YYYY") -> 1971 | Y11: =VALUE(X11) -> 1971 | Z11: =TEXT(V11,"d") -> 7 | AA11: =VALUE(Z11) -> 7 | AB11: =TEXT(V11,"dddd") -> Thursday
A12: tt0067185 | B12: Harold and Maude | C12: Harold and Maude | D12: 0 | E12: 91 | F12: =INT(E12/60) -> 1 | G12: =MOD(E12,60) -> 31 | H12: {=_xlfn.IFS(E12<=80,"Series",E12<=120,"TV Movie",E12>120,"Long Movie")} -> TV Movie | I12: Comedy | J12: Drama | K12: Romance | L12: 7.9 | M12: {=_xlfn.IFS(L12<=2,"Flop",L12<=5,"Average",L12<=7,"Hit",L12<=9,"Superhit",L12>9,"BlockBuster")} -> Superhit | N12: 80626 | O12: {=_xlfn.IFS(N12<=100000,"Low",N12<=500000,"Median",N12<=1500000,"High",N12>1500000,"Very High")} -> Low | P12: 1200000 | Q12: 1546 | R12: =Q12-P12 -> -1198454 | S12: =IF(R12>0,"Profit","Loss") -> Loss | T12: 26287 | U12: Hal Ashby | V12: 26287 | W12: =TEXT(V12,"MMMM") -> December | X12: =TEXT(V12,"YYYY") -> 1971 | Y12: =VALUE(X12) -> 1971 | Z12: =TEXT(V12,"d") -> 20 | AA12: =VALUE(Z12) -> 20 | AB12: =TEXT(V12,"dddd") -> Monday
A13: tt0067328 | B13: The Last Picture Show | C13: The Last Picture Show | D13: 0 | E13: 118 | F13: =INT(E13/60) -> 1 | G13: =MOD(E13,60) -> 58 | H13: {=_xlfn.IFS(E13<=80,"Series",E13<=120,"TV Movie",E13>120,"Long Movie")} -> TV Movie | I13: Drama | J13: Romance | K13: Unknown | L13: 8 | M13: {=_xlfn.IFS(L13<=2,"Flop",L13<=5,"Average",L13<=7,"Hit",L13<=9,"Superhit",L13>9,"BlockBuster")} -> Superhit | N13: 51275 | O13: {=_xlfn.IFS(N13<=100000,"Low",N13<=500000,"Median",N13<=1500000,"High",N13>1500000,"Very High")} -> Low | P13: 1300000 | Q13: 29146131 | R13: =Q13-P13 -> 27846131 | S13: =IF(R13>0,"Profit","Loss") -> Profit | T13: 26208 | U13: Peter Bogdanovich | V13: 26208 | W13: =TEXT(V13,"MMMM") -> October | X13: =TEXT(V13,"YYYY") -> 1971 | Y13: =VALUE(X13) -> 1971 | Z13: =TEXT(V13,"d") -> 2 | AA13: =VALUE(Z13) -> 2 | AB13: =TEXT(V13,"dddd") -> Saturday
... A466: tt0106977 | B466: The Fugitive | C466: The Fugitive | D466: 0 | E466: 130 | F466: =INT(E466/60) -> 2 | G466: =MOD(E466,60) -> 10 | H466: {=_xlfn.IFS(E466<=80,"Series",E466<=120,"TV Movie",E466>120,"Long Movie")} -> Long Movie | I466: Action | J466: Crime | K466: Drama | L466: 7.8 | M466: {=_xlfn.IFS(L466<=2,"Flop",L466<=5,"Average",L466<=7,"Hit",L466<=9,"Superhit",L466>9,"BlockBuster")} -> Superhit | N466: 310966 | O466: {=_xlfn.IFS(N466<=100000,"Low",N466<=500000,"Median",N466<=1500000,"High",N466>1500000,"Very High")} -> Median | P466: 44000000 | Q466: 368875760 | R466: =Q466-P466 -> 324875760 | S466: =IF(R466>0,"Profit","Loss") -> Profit | T466: 34179 | U466: Andrew Davis | V466: 34179 | W466: =TEXT(V466,"MMMM") -> July | X466: =TEXT(V466,"YYYY") -> 1993 | Y466: =VALUE(X466) -> 1993 | Z466: =TEXT(V466,"d") -> 29 | AA466: =VALUE(Z466) -> 29 | AB466: =TEXT(V466,"dddd") -> Thursday
A467: tt0107048 | B467: Groundhog Day | C467: Groundhog Day | D467: 0 | E467: 101 | F467: =INT(E467/60) -> 1 | G467: =MOD(E467,60) -> 41 | H467: {=_xlfn.IFS(E467<=80,"Series",E467<=120,"TV Movie",E467>120,"Long Movie")} -> TV Movie | I467: Comedy | J467: Drama | K467: Fantasy | L467: 8 | M467: {=_xlfn.IFS(L467<=2,"Flop",L467<=5,"Average",L467<=7,"Hit",L467<=9,"Superhit",L467>9,"BlockBuster")} -> Superhit | N467: 666512 | O467: {=_xlfn.IFS(N467<=100000,"Low",N467<=500000,"Median",N467<=1500000,"High",N467>1500000,"Very High")} -> High | P467: 14600000 | Q467: 71108591 | R467: =Q467-P467 -> 56508591 | S467: =IF(R467>0,"Profit","Loss") -> Profit | T467: NA | U467: Harold Ramis | V467: NA | W467: =TEXT(V467,"MMMM") -> NA | X467: =TEXT(V467,"YYYY") -> NA | Y467: =VALUE(X467) -> #VALUE! | Z467: =TEXT(V467,"d") -> NA | AA467: =VALUE(Z467) -> #VALUE! | AB467: =TEXT(V467,"dddd") -> NA
A468: tt0107076 | B468: Hard Target | C468: Hard Target | D468: 0 | E468: 97 | F468: =INT(E468/60) -> 1 | G468: =MOD(E468,60) -> 37 | H468: {=_xlfn.IFS(E468<=80,"Series",E468<=120,"TV Movie",E468>120,"Long Movie")} -> TV Movie | I468: Action | J468: Crime | K468: Thriller | L468: 6.2 | M468: {=_xlfn.IFS(L468<=2,"Flop",L468<=5,"Average",L468<=7,"Hit",L468<=9,"Superhit",L468>9,"BlockBuster")} -> Hit | N468: 54931 | O468: {=_xlfn.IFS(N468<=100000,"Low",N468<=500000,"Median",N468<=1500000,"High",N468>1500000,"Very High")} -> Low | P468: 18000000 | Q468: 74189677 | R468: =Q468-P468 -> 56189677 | S468: =IF(R468>0,"Profit","Loss") -> Profit | T468: 34201 | U468: John Woo | V468: 34201 | W468: =TEXT(V468,"MMMM") -> August | X468: =TEXT(V468,"YYYY") -> 1993 | Y468: =VALUE(X468) -> 1993 | Z468: =TEXT(V468,"d") -> 20 | AA468: =VALUE(Z468) -> 20 | AB468: =TEXT(V468,"dddd") -> Friday
A469: tt0107120 | B469: Hocus Pocus | C469: Hocus Pocus | D469: 0 | E469: 96 | F469: =INT(E469/60) -> 1 | G469: =MOD(E469,60) -> 36 | H469: {=_xlfn.IFS(E469<=80,"Series",E469<=120,"TV Movie",E469>120,"Long Movie")} -> TV Movie | I469: Comedy | J469: Family | K469: Fantasy | L469: 6.9 | M469: {=_xlfn.IFS(L469<=2,"Flop",L469<=5,"Average",L469<=7,"Hit",L469<=9,"Superhit",L469>9,"BlockBuster")} -> Hit | N469: 153494 | O469: {=_xlfn.IFS(N469<=100000,"Low",N469<=500000,"Median",N469<=1500000,"High",N469>1500000,"Very High")} -> Median | P469: 28000000 | Q469: 50789441 | R469: =Q469-P469 -> 22789441 | S469: =IF(R469>0,"Profit","Loss") -> Profit | T469: 34160 | U469: Kenny Ortega | V469: 34160 | W469: =TEXT(V469,"MMMM") -> July | X469: =TEXT(V469,"YYYY") -> 1993 | Y469: =VALUE(X469) -> 1993 | Z469: =TEXT(V469,"d") -> 10 | AA469: =VALUE(Z469) -> 10 | AB469: =TEXT(V469,"dddd") -> Saturday
A470: tt0107144 | B470: Hot Shots! Part Deux | C470: Hot Shots! Part Deux | D470: 0 | E470: 86 | F470: =INT(E470/60) -> 1 | G470: =MOD(E470,60) -> 26 | H470: {=_xlfn.IFS(E470<=80,"Series",E470<=120,"TV Movie",E470>120,"Long Movie")} -> TV Movie | I470: Action | J470: Comedy | K470: Unknown | L470: 6.6 | M470: {=_xlfn.IFS(L470<=2,"Flop",L470<=5,"Average",L470<=7,"Hit",L470<=9,"Superhit",L470>9,"BlockBuster")} -> Hit | N470: 95577 | O470: {=_xlfn.IFS(N470<=100000,"Low",N470<=500000,"Median",N470<=1500000,"High",N470>1500000,"Very High")} -> Low | P470: 25000000 | Q470: 133752825 | R470: =Q470-P470 -> 108752825 | S470: =IF(R470>0,"Profit","Loss") -> Profit | T470: 34110 | U470: Jim Abrahams | V470: 34110 | W470: =TEXT(V470,"MMMM") -> May | X470: =TEXT(V470,"YYYY") -> 1993 | Y470: =VALUE(X470) -> 1993 | Z470: =TEXT(V470,"d") -> 21 | AA470: =VALUE(Z470) -> 21 | AB470: =TEXT(V470,"dddd") -> Friday
A471: tt0107206 | B471: In the Line of Fire | C471: In the Line of Fire | D471: 0 | E471: 128 | F471: =INT(E471/60) -> 2 | G471: =MOD(E471,60) -> 8 | H471: {=_xlfn.IFS(E471<=80,"Series",E471<=120,"TV Movie",E471>120,"Long Movie")} -> Long Movie | I471: Action | J471: Crime | K471: Drama | L471: 7.2 | M471: {=_xlfn.IFS(L471<=2,"Flop",L471<=5,"Average",L471<=7,"Hit",L471<=9,"Superhit",L471>9,"BlockBuster")} -> Superhit | N471: 111126 | O471: {=_xlfn.IFS(N471<=100000,"Low",N471<=500000,"Median",N471<=1500000,"High",N471>1500000,"Very High")} -> Median | P471: 40000000 | Q471: 176997168 | R471: =Q471-P471 -> 136997168 | S471: =IF(R471>0,"Profit","Loss") -> Profit | T471: 34158 | U471: Wolfgang Petersen | V471: 34158 | W471: =TEXT(V471,"MMMM") -> July | X471: =TEXT(V471,"YYYY") -> 1993 | Y471: =VALUE(X471) -> 1993 | Z471: =TEXT(V471,"d") -> 8 | AA471: =VALUE(Z471) -> 8 | AB471: =TEXT(V471,"dddd") -> Thursday
A472: tt0107207 | B472: In the Name of the Father | C472: In the Name of the Father | D472: 0 | E472: 133 | F472: =INT(E472/60) -> 2 | G472: =MOD(E472,60) -> 13 | H472: {=_xlfn.IFS(E472<=80,"Series",E472<=120,"TV Movie",E472>120,"Long Movie")} -> Long Movie | I472: Biography | J472: Crime | K472: Drama | L472: 8.1 | M472: {=_xlfn.IFS(L472<=2,"Flop",L472<=5,"Average",L472<=7,"Hit",L472<=9,"Superhit",L472>9,"BlockBuster")} -> Superhit | N472: 183546 | O472: {=_xlfn.IFS(N472<=100000,"Low",N472<=500000,"Median",N472<=1500000,"High",N472>1500000,"Very High")} -> Median | P472: 13000000 | Q472: 65796862 | R472: =Q472-P472 -> 52796862 | S472: =IF(R472>0,"Profit","Loss") -> Profit | T472: 34315 | U472: Jim Sheridan | V472: 34315 | W472: =TEXT(V472,"MMMM") -> December | X472: =TEXT(V472,"YYYY") -> 1993 | Y472: =VALUE(X472) -> 1993 | Z472: =TEXT(V472,"d") -> 12 | AA472: =VALUE(Z472) -> 12 | AB472: =TEXT(V472,"dddd") -> Sunday
A473: tt0107211 | B473: Indecent Proposal | C473: Indecent Proposal | D473: 0 | E473: 117 | F473: =INT(E473/60) -> 1 | G473: =MOD(E473,60) -> 57 | H473: {=_xlfn.IFS(E473<=80,"Series",E473<=120,"TV Movie",E473>120,"Long Movie")} -> TV Movie | I473: Drama | J473: Romance | K473: Unknown | L473: 6 | M473: {=_xlfn.IFS(L473<=2,"Flop",L473<=5,"Average",L473<=7,"Hit",L473<=9,"Superhit",L473>9,"BlockBuster")} -> Hit | N473: 76245 | O473: {=_xlfn.IFS(N473<=100000,"Low",N473<=500000,"Median",N473<=1500000,"High",N473>1500000,"Very High")} -> Low | P473: 38000000 | Q473: 266614059 | R473: =Q473-P473 -> 228614059 | S473: =IF(R473>0,"Profit","Loss") -> Profit | T473: 34065 | U473: Adrian Lyne | V473: 34065 | W473: =TEXT(V473,"MMMM") -> April | X473: =TEXT(V473,"YYYY") -> 1993 | Y473: =VALUE(X473) -> 1993 | Z473: =TEXT(V473,"d") -> 6 | AA473: =VALUE(Z473) -> 6 | AB473: =TEXT(V473,"dddd") -> Tuesday
A474: tt0107290 | B474: Jurassic Park | C474: Jurassic Park | D474: 0 | E474: 127 | F474: =INT(E474/60) -> 2 | G474: =MOD(E474,60) -> 7 | H474: {=_xlfn.IFS(E474<=80,"Series",E474<=120,"TV Movie",E474>120,"Long Movie")} -> Long Movie | I474: Action | J474: Adventure | K474: Sci-Fi | L474: 8.2 | M474: {=_xlfn.IFS(L474<=2,"Flop",L474<=5,"Average",L474<=7,"Hit",L474<=9,"Superhit",L474>9,"BlockBuster")} -> Superhit | N474: 1041089 | O474: {=_xlfn.IFS(N474<=100000,"Low",N474<=500000,"Median",N474<=1500000,"High",N474>1500000,"Very High")} -> High | P474: 63000000 | Q474: 1113138548 | R474: =Q474-P474 -> 1050138548 | S474: =IF(R474>0,"Profit","Loss") -> Profit | T474: 34129 | U474: Steven Spielberg | V474: 34129 | W474: =TEXT(V474,"MMMM") -> June | X474: =TEXT(V474,"YYYY") -> 1993 | Y474: =VALUE(X474) -> 1993 | Z474: =TEXT(V474,"d") -> 9 | AA474: =VALUE(Z474) -> 9 | AB474: =TEXT(V474,"dddd") -> Wednesday
A475: tt0107302 | B475: Kalifornia | C475: Kalifornia | D475: 0 | E475: 117 | F475: =INT(E475/60) -> 1 | G475: =MOD(E475,60) -> 57 | H475: {=_xlfn.IFS(E475<=80,"Series",E475<=120,"TV Movie",E475>120,"Long Movie")} -> TV Movie | I475: Crime | J475: Drama | K475: Thriller | L475: 6.7 | M475: {=_xlfn.IFS(L475<=2,"Flop",L475<=5,"Average",L475<=7,"Hit",L475<=9,"Superhit",L475>9,"BlockBuster")} -> Hit | N475: 56797 | O475: {=_xlfn.IFS(N475<=100000,"Low",N475<=500000,"Median",N475<=1500000,"High",N475>1500000,"Very High")} -> Low | P475: 9000000 | Q475: 2395231 | R475: =Q475-P475 -> -6604769 | S475: =IF(R475>0,"Profit","Loss") -> Loss | T475: 34182 | U475: Dominic Sena | V475: 34182 | W475: =TEXT(V475,"MMMM") -> August | X475: =TEXT(V475,"YYYY") -> 1993 | Y475: =VALUE(X475) -> 1993 | Z475: =TEXT(V475,"d") -> 1 | AA475: =VALUE(Z475) -> 1 | AB475: =TEXT(V475,"dddd") -> Sunday
A476: tt0107362 | B476: Last Action Hero | C476: Last Action Hero | D476: 0 | E476: 130 | F476: =INT(E476/60) -> 2 | G476: =MOD(E476,60) -> 10 | H476: {=_xlfn.IFS(E476<=80,"Series",E476<=120,"TV Movie",E476>120,"Long Movie")} -> Long Movie | I476: Action | J476: Adventure | K476: Comedy | L476: 6.5 | M476: {=_xlfn.IFS(L476<=2,"Flop",L476<=5,"Average",L476<=7,"Hit",L476<=9,"Superhit",L476>9,"BlockBuster")} -> Hit | N476: 160479 | O476: {=_xlfn.IFS(N476<=100000,"Low",N476<=500000,"Median",N476<=1500000,"High",N476>1500000,"Very High")} -> Median | P476: 85000000 | Q476: 137298489 | R476: =Q476-P476 -> 52298489 | S476: =IF(R476>0,"Profit","Loss") -> Profit | T476: 34133 | U476: John McTiernan | V476: 34133 | W476: =TEXT(V476,"MMMM") -> June | X476: =TEXT(V476,"YYYY") -> 1993 | Y476: =VALUE(X476) -> 1993 | Z476: =TEXT(V476,"d") -> 13 | AA476: =VALUE(Z476) -> 13 | AB476: =TEXT(V476,"dddd") -> Sunday
A477: tt0107554 | B477: Menace II Society | C477: Menace II Society | D477: 0 | E477: 97 | F477: =INT(E477/60) -> 1 | G477: =MOD(E477,60) -> 37 | H477: {=_xlfn.IFS(E477<=80,"Series",E477<=120,"TV Movie",E477>120,"Long Movie")} -> TV Movie | I477: Crime | J477: Drama | K477: Thriller | L477: 7.5 | M477: {=_xlfn.IFS(L477<=2,"Flop",L477<=5,"Average",L477<=7,"Hit",L477<=9,"Superhit",L477>9,"BlockBuster")} -> Superhit | N477: 63036 | O477: {=_xlfn.IFS(N477<=100000,"Low",N477<=500000,"Median",N477<=1500000,"High",N477>1500000,"Very High")} -> Low | P477: 3500000 | Q477: 27912072 | R477: =Q477-P477 -> 24412072 | S477: =IF(R477>0,"Profit","Loss") -> Profit | T477: 34115 | U477: Albert Hughes, Allen Hughes | V477: 34115 | W477: =TEXT(V477,"MMMM") -> May | X477: =TEXT(V477,"YYYY") -> 1993 | Y477: =VALUE(X477) -> 1993 | Z477: =TEXT(V477,"d") -> 26 | AA477: =VALUE(Z477) -> 26 | AB477: =TEXT(V477,"dddd") -> Wednesday
A478: tt0107614 | B478: Mrs. Doubtfire | C478: Mrs. Doubtfire | D478: 0 | E478: 125 | F478: =INT(E478/60) -> 2 | G478: =MOD(E478,60) -> 5 | H478: {=_xlfn.IFS(E478<=80,"Series",E478<=120,"TV Movie",E478>120,"Long Movie")} -> Long Movie | I478: Comedy | J478: Drama | K478: Unknown | L478: 7.1 | M478: {=_xlfn.IFS(L478<=2,"Flop",L478<=5,"Average",L478<=7,"Hit",L478<=9,"Superhit",L478>9,"BlockBuster")} -> Superhit | N478: 283743 | O478: {=_xlfn.IFS(N478<=100000,"Low",N478<=500000,"Median",N478<=1500000,"High",N478>1500000,"Very High")} -> Median | P478: 25000000 | Q478: 441286195 | R478: =Q478-P478 -> 416286195 | S478: =IF(R478>0,"Profit","Loss") -> Profit | T478: 34295 | U478: Chris Columbus | V478: 34295 | W478: =TEXT(V478,"MMMM") -> November | X478: =TEXT(V478,"YYYY") -> 1993 | Y478: =VALUE(X478) -> 1993 | Z478: =TEXT(V478,"d") -> 22 | AA478: =VALUE(Z478) -> 22 | AB478: =TEXT(V478,"dddd") -> Monday
A479: tt0107616 | B479: Much Ado About Nothing | C479: Much Ado About Nothing | D479: 0 | E479: 111 | F479: =INT(E479/60) -> 1 | G479: =MOD(E479,60) -> 51 | H479: {=_xlfn.IFS(E479<=80,"Series",E479<=120,"TV Movie",E479>120,"Long Movie")} -> TV Movie | I479: Comedy | J479: Drama | K479: Romance | L479: 7.3 | M479: {=_xlfn.IFS(L479<=2,"Flop",L479<=5,"Average",L479<=7,"Hit",L479<=9,"Superhit",L479>9,"BlockBuster")} -> Superhit | N479: 50854 | O479: {=_xlfn.IFS(N479<=100000,"Low",N479<=500000,"Median",N479<=1500000,"High",N479>1500000,"Very High")} -> Low | P479: 11000000 | Q479: 22549338 | R479: =Q479-P479 -> 11549338 | S479: =IF(R479>0,"Profit","Loss") -> Profit | T479: 34095 | U479: Kenneth Branagh | V479: 34095 | W479: =TEXT(V479,"MMMM") -> May | X479: =TEXT(V479,"YYYY") -> 1993 | Y479: =VALUE(X479) -> 1993 | Z479: =TEXT(V479,"d") -> 6 | AA479: =VALUE(Z479) -> 6 | AB479: =TEXT(V479,"dddd") -> Thursday
... A525: tt0110912 | B525: Pulp Fiction | C525: Pulp Fiction | D525: 0 | E525: 154 | F525: =INT(E525/60) -> 2 | G525: =MOD(E525,60) -> 34 | H525: {=_xlfn.IFS(E525<=80,"Series",E525<=120,"TV Movie",E525>120,"Long Movie")} -> Long Movie | I525: Crime | J525: Drama | K525: Unknown | L525: 8.9 | M525: {=_xlfn.IFS(L525<=2,"Flop",L525<=5,"Average",L525<=7,"Hit",L525<=9,"Superhit",L525>9,"BlockBuster")} -> Superhit | N525: 2160463 | O525: {=_xlfn.IFS(N525<=100000,"Low",N525<=500000,"Median",N525<=1500000,"High",N525>1500000,"Very High")} -> Very High | P525: 8000000 | Q525: 213928762 | R525: =Q525-P525 -> 205928762 | S525: =IF(R525>0,"Profit","Loss") -> Profit | T525: 34475 | U525: Quentin Tarantino | V525: 34475 | W525: =TEXT(V525,"MMMM") -> May | X525: =TEXT(V525,"YYYY") -> 1994 | Y525: =VALUE(X525) -> 1994 | Z525: =TEXT(V525,"d") -> 21 | AA525: =VALUE(Z525) -> 21 | AB525: =TEXT(V525,"dddd") -> Saturday
A526: tt0110932 | B526: Quiz Show | C526: Quiz Show | D526: 0 | E526: 133 | F526: =INT(E526/60) -> 2 | G526: =MOD(E526,60) -> 13 | H526: {=_xlfn.IFS(E526<=80,"Series",E526<=120,"TV Movie",E526>120,"Long Movie")} -> Long Movie | I526: Biography | J526: Drama | K526: History | L526: 7.5 | M526: {=_xlfn.IFS(L526<=2,"Flop",L526<=5,"Average",L526<=7,"Hit",L526<=9,"Superhit",L526>9,"BlockBuster")} -> Superhit | N526: 72316 | O526: {=_xlfn.IFS(N526<=100000,"Low",N526<=500000,"Median",N526<=1500000,"High",N526>1500000,"Very High")} -> Low | P526: 31000000 | Q526: 24822619 | R526: =Q526-P526 -> -6177381 | S526: =IF(R526>0,"Profit","Loss") -> Loss | T526: NA | U526: Robert Redford | V526: NA | W526: =TEXT(V526,"MMMM") -> NA | X526: =TEXT(V526,"YYYY") -> NA | Y526: =VALUE(X526) -> #VALUE! | Z526: =TEXT(V526,"d") -> NA | AA526: =VALUE(Z526) -> #VALUE! | AB526: =TEXT(V526,"dddd") -> NA
A527: tt0110950 | B527: Reality Bites | C527: Reality Bites | D527: 0 | E527: 99 | F527: =INT(E527/60) -> 1 | G527: =MOD(E527,60) -> 39 | H527: {=_xlfn.IFS(E527<=80,"Series",E527<=120,"TV Movie",E527>120,"Long Movie")} -> TV Movie | I527: Comedy | J527: Drama | K527: Romance | L527: 6.6 | M527: {=_xlfn.IFS(L527<=2,"Flop",L527<=5,"Average",L527<=7,"Hit",L527<=9,"Superhit",L527>9,"BlockBuster")} -> Hit | N527: 52717 | O527: {=_xlfn.IFS(N527<=100000,"Low",N527<=500000,"Median",N527<=1500000,"High",N527>1500000,"Very High")} -> Low | P527: 11500000 | Q527: 33351557 | R527: =Q527-P527 -> 21851557 | S527: =IF(R527>0,"Profit","Loss") -> Profit | T527: 34335 | U527: Ben Stiller | V527: 34335 | W527: =TEXT(V527,"MMMM") -> January | X527: =TEXT(V527,"YYYY") -> 1994 | Y527: =VALUE(X527) -> 1994 | Z527: =TEXT(V527,"d") -> 1 | AA527: =VALUE(Z527) -> 1 | AB527: =TEXT(V527,"dddd") -> Saturday
A528: tt0110989 | B528: Richie Rich | C528: RiÂ¢hie RiÂ¢h | D528: 0 | E528: 95 | F528: =INT(E528/60) -> 1 | G528: =MOD(E528,60) -> 35 | H528: {=_xlfn.IFS(E528<=80,"Series",E528<=120,"TV Movie",E528>120,"Long Movie")} -> TV Movie | I528: Comedy | J528: Family | K528: Unknown | L528: 5.4 | M528: {=_xlfn.IFS(L528<=2,"Flop",L528<=5,"Average",L528<=7,"Hit",L528<=9,"Superhit",L528>9,"BlockBuster")} -> Hit | N528: 72205 | O528: {=_xlfn.IFS(N528<=100000,"Low",N528<=500000,"Median",N528<=1500000,"High",N528>1500000,"Very High")} -> Low | P528: 40000000 | Q528: 38087756 | R528: =Q528-P528 -> -1912244 | S528: =IF(R528>0,"Profit","Loss") -> Loss | T528: 34687 | U528: Donald Petrie | V528: 34687 | W528: =TEXT(V528,"MMMM") -> December | X528: =TEXT(V528,"YYYY") -> 1994 | Y528: =VALUE(X528) -> 1994 | Z528: =TEXT(V528,"d") -> 19 | AA528: =VALUE(Z528) -> 19 | AB528: =TEXT(V528,"dddd") -> Monday
A529: tt0111070 | B529: The Santa Clause | C529: The Santa Clause | D529: 0 | E529: 97 | F529: =INT(E529/60) -> 1 | G529: =MOD(E529,60) -> 37 | H529: {=_xlfn.IFS(E529<=80,"Series",E529<=120,"TV Movie",E529>120,"Long Movie")} -> TV Movie | I529: Comedy | J529: Drama | K529: Family | L529: 6.5 | M529: {=_xlfn.IFS(L529<=2,"Flop",L529<=5,"Average",L529<=7,"Hit",L529<=9,"Superhit",L529>9,"BlockBuster")} -> Hit | N529: 126968 | O529: {=_xlfn.IFS(N529<=100000,"Low",N529<=500000,"Median",N529<=1500000,"High",N529>1500000,"Very High")} -> Median | P529: 22000000 | Q529: 190539357 | R529: =Q529-P529 -> 168539357 | S529: =IF(R529>0,"Profit","Loss") -> Profit | T529: 34649 | U529: John Pasquin | V529: 34649 | W529: =TEXT(V529,"MMMM") -> November | X529: =TEXT(V529,"YYYY") -> 1994 | Y529: =VALUE(X529) -> 1994 | Z529: =TEXT(V529,"d") -> 11 | AA529: =VALUE(Z529) -> 11 | AB529: =TEXT(V529,"dddd") -> Friday
A530: tt0111149 | B530: Shallow Grave | C530: Shallow Grave | D530: 0 | E530: 89 | F530: =INT(E530/60) -> 1 | G530: =MOD(E530,60) -> 29 | H530: {=_xlfn.IFS(E530<=80,"Series",E530<=120,"TV Movie",E530>120,"Long Movie")} -> TV Movie | I530: Crime | J530: Drama | K530: Thriller | L530: 7.3 | M530: {=_xlfn.IFS(L530<=2,"Flop",L530<=5,"Average",L530<=7,"Hit",L530<=9,"Superhit",L530>9,"BlockBuster")} -> Superhit | N530: 65075 | O530: {=_xlfn.IFS(N530<=100000,"Low",N530<=500000,"Median",N530<=1500000,"High",N530>1500000,"Very High")} -> Low | P530: 2500000 | Q530: 2079569 | R530: =Q530-P530 -> -420431 | S530: =IF(R530>0,"Profit","Loss") -> Loss | T530: 34471 | U530: Danny Boyle | V530: 34471 | W530: =TEXT(V530,"MMMM") -> May | X530: =TEXT(V530,"YYYY") -> 1994 | Y530: =VALUE(X530) -> 1994 | Z530: =TEXT(V530,"d") -> 17 | AA530: =VALUE(Z530) -> 17 | AB530: =TEXT(V530,"dddd") -> Tuesday
A531: tt0111161 | B531: The Shawshank Redemption | C531: The Shawshank Redemption | D531: 0 | E531: 142 | F531: =INT(E531/60) -> 2 | G531: =MOD(E531,60) -> 22 | H531: {=_xlfn.IFS(E531<=80,"Series",E531<=120,"TV Movie",E531>120,"Long Movie")} -> Long Movie | I531: Drama | J531: Unknown | K531: Unknown | L531: 9.3 | M531: {=_xlfn.IFS(L531<=2,"Flop",L531<=5,"Average",L531<=7,"Hit",L531<=9,"Superhit",L531>9,"BlockBuster")} -> BlockBuster | N531: 2817283 | O531: {=_xlfn.IFS(N531<=100000,"Low",N531<=500000,"Median",N531<=1500000,"High",N531>1500000,"Very High")} -> Very High | P531: 25000000 | Q531: 28884716 | R531: =Q531-P531 -> 3884716 | S531: =IF(R531>0,"Profit","Loss") -> Profit | T531: 34587 | U531: Frank Darabont | V531: 34587 | W531: =TEXT(V531,"MMMM") -> September | X531: =TEXT(V531,"YYYY") -> 1994 | Y531: =VALUE(X531) -> 1994 | Z531: =TEXT(V531,"d") -> 10 | AA531: =VALUE(Z531) -> 10 | AB531: =TEXT(V531,"dddd") -> Saturday
A532: tt0111255 | B532: The Specialist | C532: The Specialist | D532: 0 | E532: 110 | F532: =INT(E532/60) -> 1 | G532: =MOD(E532,60) -> 50 | H532: {=_xlfn.IFS(E532<=80,"Series",E532<=120,"TV Movie",E532>120,"Long Movie")} -> TV Movie | I532: Action | J532: Drama | K532: Thriller | L532: 5.6 | M532: {=_xlfn.IFS(L532<=2,"Flop",L532<=5,"Average",L532<=7,"Hit",L532<=9,"Superhit",L532>9,"BlockBuster")} -> Hit | N532: 68821 | O532: {=_xlfn.IFS(N532<=100000,"Low",N532<=500000,"Median",N532<=1500000,"High",N532>1500000,"Very High")} -> Low | P532: 45000000 | Q532: 170362582 | R532: =Q532-P532 -> 125362582 | S532: =IF(R532>0,"Profit","Loss") -> Profit | T532: 34614 | U532: Luis Llosa | V532: 34614 | W532: =TEXT(V532,"MMMM") -> October | X532: =TEXT(V532,"YYYY") -> 1994 | Y532: =VALUE(X532) -> 1994 | Z532: =TEXT(V532,"d") -> 7 | AA532: =VALUE(Z532) -> 7 | AB532: =TEXT(V532,"dddd") -> Friday
A533: tt0111257 | B533: Speed | C533: Speed | D533: 0 | E533: 116 | F533: =INT(E533/60) -> 1 | G533: =MOD(E533,60) -> 56 | H533: {=_xlfn.IFS(E533<=80,"Series",E533<=120,"TV Movie",E533>120,"Long Movie")} -> TV Movie | I533: Action | J533: Adventure | K533: Thriller | L533: 7.3 | M533: {=_xlfn.IFS(L533<=2,"Flop",L533<=5,"Average",L533<=7,"Hit",L533<=9,"Superhit",L533>9,"BlockBuster")} -> Superhit | N533: 383702 | O533: {=_xlfn.IFS(N533<=100000,"Low",N533<=500000,"Median",N533<=1500000,"High",N533>1500000,"Very High")} -> Median | P533: 30000000 | Q533: 350448145 | R533: =Q533-P533 -> 320448145 | S533: =IF(R533>0,"Profit","Loss") -> Profit | T533: 34492 | U533: Jan de Bont | V533: 34492 | W533: =TEXT(V533,"MMMM") -> June | X533: =TEXT(V533,"YYYY") -> 1994 | Y533: =VALUE(X533) -> 1994 | Z533: =TEXT(V533,"d") -> 7 | AA533: =VALUE(Z533) -> 7 | AB533: =TEXT(V533,"dddd") -> Tuesday
A534: tt0111280 | B534: Star Trek: Generations | C534: Star Trek: Generations | D534: 0 | E534: 118 | F534: =INT(E534/60) -> 1 | G534: =MOD(E534,60) -> 58 | H534: {=_xlfn.IFS(E534<=80,"Series",E534<=120,"TV Movie",E534>120,"Long Movie")} -> TV Movie | I534: Action | J534: Adventure | K534: Mystery | L534: 6.6 | M534: {=_xlfn.IFS(L534<=2,"Flop",L534<=5,"Average",L534<=7,"Hit",L534<=9,"Superhit",L534>9,"BlockBuster")} -> Hit | N534: 85822 | O534: {=_xlfn.IFS(N534<=100000,"Low",N534<=500000,"Median",N534<=1500000,"High",N534>1500000,"Very High")} -> Low | P534: 35000000 | Q534: 118071125 | R534: =Q534-P534 -> 83071125 | S534: =IF(R534>0,"Profit","Loss") -> Profit | T534: 34655 | U534: David Carson | V534: 34655 | W534: =TEXT(V534,"MMMM") -> November | X534: =TEXT(V534,"YYYY") -> 1994 | Y534: =VALUE(X534) -> 1994 | Z534: =TEXT(V534,"d") -> 17 | AA534: =VALUE(Z534) -> 17 | AB534: =TEXT(V534,"dddd") -> Thursday
A535: tt0111282 | B535: Stargate | C535: Stargate | D535: 0 | E535: 116 | F535: =INT(E535/60) -> 1 | G535: =MOD(E535,60) -> 56 | H535: {=_xlfn.IFS(E535<=80,"Series",E535<=120,"TV Movie",E535>120,"Long Movie")} -> TV Movie | I535: Action | J535: Adventure | K535: Sci-Fi | L535: 7 | M535: {=_xlfn.IFS(L535<=2,"Flop",L535<=5,"Average",L535<=7,"Hit",L535<=9,"Superhit",L535>9,"BlockBuster")} -> Hit | N535: 200994 | O535: {=_xlfn.IFS(N535<=100000,"Low",N535<=500000,"Median",N535<=1500000,"High",N535>1500000,"Very High")} -> Median | P535: 55000000 | Q535: 196567262 | R535: =Q535-P535 -> 141567262 | S535: =IF(R535>0,"Profit","Loss") -> Profit | T535: 34635 | U535: Roland Emmerich | V535: 34635 | W535: =TEXT(V535,"MMMM") -> October | X535: =TEXT(V535,"YYYY") -> 1994 | Y535: =VALUE(X535) -> 1994 | Z535: =TEXT(V535,"d") -> 28 | AA535: =VALUE(Z535) -> 28 | AB535: =TEXT(V535,"dddd") -> Friday
A536: tt0111301 | B536: Street Fighter | C536: Street Fighter | D536: 0 | E536: 102 | F536: =INT(E536/60) -> 1 | G536: =MOD(E536,60) -> 42 | H536: {=_xlfn.IFS(E536<=80,"Series",E536<=120,"TV Movie",E536>120,"Long Movie")} -> TV Movie | I536: Action | J536: Adventure | K536: Comedy | L536: 4 | M536: {=_xlfn.IFS(L536<=2,"Flop",L536<=5,"Average",L536<=7,"Hit",L536<=9,"Superhit",L536>9,"BlockBuster")} -> Average | N536: 74256 | O536: {=_xlfn.IFS(N536<=100000,"Low",N536<=500000,"Median",N536<=1500000,"High",N536>1500000,"Very High")} -> Low | P536: 35000000 | Q536: 99431786 | R536: =Q536-P536 -> 64431786 | S536: =IF(R536>0,"Profit","Loss") -> Profit | T536: 34691 | U536: Steven E. de Souza | V536: 34691 | W536: =TEXT(V536,"MMMM") -> December | X536: =TEXT(V536,"YYYY") -> 1994 | Y536: =VALUE(X536) -> 1994 | Z536: =TEXT(V536,"d") -> 23 | AA536: =VALUE(Z536) -> 23 | AB536: =TEXT(V536,"dddd") -> Friday
A537: tt0111438 | B537: Timecop | C537: Timecop | D537: 0 | E537: 99 | F537: =INT(E537/60) -> 1 | G537: =MOD(E537,60) -> 39 | H537: {=_xlfn.IFS(E537<=80,"Series",E537<=120,"TV Movie",E537>120,"Long Movie")} -> TV Movie | I537: Action | J537: Crime | K537: Sci-Fi | L537: 5.9 | M537: {=_xlfn.IFS(L537<=2,"Flop",L537<=5,"Average",L537<=7,"Hit",L537<=9,"Superhit",L537>9,"BlockBuster")} -> Hit | N537: 62760 | O537: {=_xlfn.IFS(N537<=100000,"Low",N537<=500000,"Median",N537<=1500000,"High",N537>1500000,"Very High")} -> Low | P537: 27000000 | Q537: 101646581 | R537: =Q537-P537 -> 74646581 | S537: =IF(R537>0,"Profit","Loss") -> Profit | T537: 34593 | U537: Peter Hyams | V537: 34593 | W537: =TEXT(V537,"MMMM") -> September | X537: =TEXT(V537,"YYYY") -> 1994 | Y537: =VALUE(X537) -> 1994 | Z537: =TEXT(V537,"d") -> 16 | AA537: =VALUE(Z537) -> 16 | AB537: =TEXT(V537,"dddd") -> Friday
...

Sheet Clean Sheet
A1: id | B1: primaryTitle | C1: originalTitle | D1: isAdult | E1: runtimeMinutes | F1: Hour | G1: Minutes | H1: Runtime Classification | I1: Genres1 | J1: Genres2 | K1: Genres3 | L1: averageRating | M1: Movie Type | N1: numVotes | O1: Vote Category | P1: budget | Q1: gross | R1: Profit | S1: Profit & Loss | T1: release_date | U1: directors | V1: Release_Date | W1: Month | X1: DayName | Y1: year1 | Z1: day 1
A2: tt0035423 | B2: Kate & Leopold | C2: Kate & Leopold | D2: 0 | E2: 118 | F2: 1 | G2: 58 | H2: TV Movie | I2: Comedy | J2: Fantasy | K2: Romance | L2: 6.4 | M2: Hit | N2: 87925 | O2: Low | P2: 48000000 | Q2: 76019048 | R2: 28019048 | S2: Profit | T2: 37236 | U2: James Mangold | V2: 37236 | W2: December | X2: Tuesday | Y2: 2001 | Z2: 11
A3: tt0065421 | B3: The Aristocats | C3: The AristoCats | D3: 0 | E3: 78 | F3: 1 | G3: 18 | H3: Series | I3: Adventure | J3: Animation | K3: Comedy | L3: 7.1 | M3: Superhit | N3: 111758 | O3: Median | P3: 4000000 | Q3: 35459543 | R3: 31459543 | S3: Profit | T3: 25913 | U3: Wolfgang Reitherman | V3: 25913 | W3: December | X3: Friday | Y3: 1970 | Z3: 11
A4: tt0065938 | B4: Kelly's Heroes | C4: Kelly's Heroes | D4: 0 | E4: 144 | F4: 2 | G4: 24 | H4: Long Movie | I4: Adventure | J4: Comedy | K4: War | L4: 7.6 | M4: Superhit | N4: 52628 | O4: Low | P4: 4000000 | Q4: 5200000 | R4: 1200000 | S4: Profit | T4: 25569 | U4: Brian G. Hutton | V4: 25569 | W4: January | X4: Thursday | Y4: 1970 | Z4: 1
A5: tt0066026 | B5: M*A*S*H | C5: M*A*S*H | D5: 0 | E5: 116 | F5: 1 | G5: 56 | H5: TV Movie | I5: Comedy | J5: Drama | K5: War | L5: 7.4 | M5: Superhit | N5: 75784 | O5: Low | P5: 3500000 | Q5: 81600000 | R5: 78100000 | S5: Profit | T5: 25593 | U5: Robert Altman | V5: 25593 | W5: January | X5: Sunday | Y5: 1970 | Z5: 25
A6: tt0066206 | B6: Patton | C6: Patton | D6: 0 | E6: 172 | F6: 2 | G6: 52 | H6: Long Movie | I6: Biography | J6: Drama | K6: War | L6: 7.9 | M6: Superhit | N6: 106476 | O6: Median | P6: 12000000 | Q6: 61749765 | R6: 49749765 | S6: Profit | T6: 25603 | U6: Franklin J. Schaffner | V6: 25603 | W6: February | X6: Wednesday | Y6: 1970 | Z6: 4
A7: tt0066434 | B7: THX 1138 | C7: THX 1138 | D7: 0 | E7: 86 | F7: 1 | G7: 26 | H7: TV Movie | I7: Drama | J7: Sci-Fi | K7: Thriller | L7: 6.6 | M7: Hit | N7: 53906 | O7: Low | P7: 777000 | Q7: 2437000 | R7: 1660000 | S7: Profit | T7: 26003 | U7: George Lucas | V7: 26003 | W7: March | X7: Thursday | Y7: 1971 | Z7: 11
A8: tt0066921 | B8: A Clockwork Orange | C8: A Clockwork Orange | D8: 0 | E8: 136 | F8: 2 | G8: 16 | H8: Long Movie | I8: Crime | J8: Sci-Fi | K8: Unknown | L8: 8.3 | M8: Superhit | N8: 864440 | O8: High | P8: 2200000 | Q8: 26960374 | R8: 24760374 | S8: Profit | T8: 26286 | U8: Stanley Kubrick | V8: 26286 | W8: December | X8: Sunday | Y8: 1971 | Z8: 19
A9: tt0066995 | B9: Diamonds Are Forever | C9: Diamonds Are Forever | D9: 0 | E9: 120 | F9: 2 | G9: 0 | H9: TV Movie | I9: Action | J9: Adventure | K9: Thriller | L9: 6.5 | M9: Hit | N9: 112043 | O9: Median | P9: 7200000 | Q9: 43829933 | R9: 36629933 | S9: Profit | T9: 26281 | U9: Guy Hamilton | V9: 26281 | W9: December | X9: Tuesday | Y9: 1971 | Z9: 14
A10: tt0066999 | B10: Dirty Harry | C10: Dirty Harry | D10: 0 | E10: 102 | F10: 1 | G10: 42 | H10: TV Movie | I10: Action | J10: Crime | K10: Thriller | L10: 7.7 | M10: Superhit | N10: 165277 | O10: Median | P10: 4000000 | Q10: 35988495 | R10: 31988495 | S10: Profit | T10: 26288 | U10: Don Siegel, Clint Eastwood | V10: 26288 | W10: December | X10: Tuesday | Y10: 1971 | Z10: 21
A11: tt0067116 | B11: The French Connection | C11: The French Connection | D11: 0 | E11: 104 | F11: 1 | G11: 44 | H11: TV Movie | I11: Action | J11: Crime | K11: Drama | L11: 7.7 | M11: Superhit | N11: 131995 | O11: Median | P11: 1800000 | Q11: 51701871 | R11: 49901871 | S11: Profit | T11: 26213 | U11: William Friedkin | V11: 26213 | W11: October | X11: Thursday | Y11: 1971 | Z11: 7
A12: tt0067185 | B12: Harold and Maude | C12: Harold and Maude | D12: 0 | E12: 91 | F12: 1 | G12: 31 | H12: TV Movie | I12: Comedy | J12: Drama | K12: Romance | L12: 7.9 | M12: Superhit | N12: 80626 | O12: Low | P12: 1200000 | Q12: 1546 | R12: -1198454 | S12: Loss | T12: 26287 | U12: Hal Ashby | V12: 26287 | W12: December | X12: Monday | Y12: 1971 | Z12: 20
A13: tt0067328 | B13: The Last Picture Show | C13: The Last Picture Show | D13: 0 | E13: 118 | F13: 1 | G13: 58 | H13: TV Movie | I13: Drama | J13: Romance | K13: Unknown | L13: 8 | M13: Superhit | N13: 51275 | O13: Low | P13: 1300000 | Q13: 29146131 | R13: 27846131 | S13: Profit | T13: 26208 | U13: Peter Bogdanovich | V13: 26208 | W13: October | X13: Saturday | Y13: 1971 | Z13: 2
... A466: tt0106977 | B466: The Fugitive | C466: The Fugitive | D466: 0 | E466: 130 | F466: 2 | G466: 10 | H466: Long Movie | I466: Action | J466: Crime | K466: Drama | L466: 7.8 | M466: Superhit | N466: 310966 | O466: Median | P466: 44000000 | Q466: 368875760 | R466: 324875760 | S466: Profit | T466: 34179 | U466: Andrew Davis | V466: 34179 | W466: July | X466: Thursday | Y466: 1993 | Z466: 29
A467: tt0107048 | B467: Groundhog Day | C467: Groundhog Day | D467: 0 | E467: 101 | F467: 1 | G467: 41 | H467: TV Movie | I467: Comedy | J467: Drama | K467: Fantasy | L467: 8 | M467: Superhit | N467: 666512 | O467: High | P467: 14600000 | Q467: 71108591 | R467: 56508591 | S467: Profit | T467: NA | U467: Harold Ramis | V467: NA | W467: NA | X467: NA | Y467: #VALUE! | Z467: #VALUE!
A468: tt0107076 | B468: Hard Target | C468: Hard Target | D468: 0 | E468: 97 | F468: 1 | G468: 37 | H468: TV Movie | I468: Action | J468: Crime | K468: Thriller | L468: 6.2 | M468: Hit | N468: 54931 | O468: Low | P468: 18000000 | Q468: 74189677 | R468: 56189677 | S468: Profit | T468: 34201 | U468: John Woo | V468: 34201 | W468: August | X468: Friday | Y468: 1993 | Z468: 20
A469: tt0107120 | B469: Hocus Pocus | C469: Hocus Pocus | D469: 0 | E469: 96 | F469: 1 | G469: 36 | H469: TV Movie | I469: Comedy | J469: Family | K469: Fantasy | L469: 6.9 | M469: Hit | N469: 153494 | O469: Median | P469: 28000000 | Q469: 50789441 | R469: 22789441 | S469: Profit | T469: 34160 | U469: Kenny Ortega | V469: 34160 | W469: July | X469: Saturday | Y469: 1993 | Z469: 10
A470: tt0107144 | B470: Hot Shots! Part Deux | C470: Hot Shots! Part Deux | D470: 0 | E470: 86 | F470: 1 | G470: 26 | H470: TV Movie | I470: Action | J470: Comedy | K470: Unknown | L470: 6.6 | M470: Hit | N470: 95577 | O470: Low | P470: 25000000 | Q470: 133752825 | R470: 108752825 | S470: Profit | T470: 34110 | U470: Jim Abrahams | V470: 34110 | W470: May | X470: Friday | Y470: 1993 | Z470: 21
A471: tt0107206 | B471: In the Line of Fire | C471: In the Line of Fire | D471: 0 | E471: 128 | F471: 2 | G471: 8 | H471: Long Movie | I471: Action | J471: Crime | K471: Drama | L471: 7.2 | M471: Superhit | N471: 111126 | O471: Median | P471: 40000000 | Q471: 176997168 | R471: 136997168 | S471: Profit | T471: 34158 | U471: Wolfgang Petersen | V471: 34158 | W471: July | X471: Thursday | Y471: 1993 | Z471: 8
A472: tt0107207 | B472: In the Name of the Father | C472: In the Name of the Father | D472: 0 | E472: 133 | F472: 2 | G472: 13 | H472: Long Movie | I472: Biography | J472: Crime | K472: Drama | L472: 8.1 | M472: Superhit | N472: 183546 | O472: Median | P472: 13000000 | Q472: 65796862 | R472: 52796862 | S472: Profit | T472: 34315 | U472: Jim Sheridan | V472: 34315 | W472: December | X472: Sunday | Y472: 1993 | Z472: 12
A473: tt0107211 | B473: Indecent Proposal | C473: Indecent Proposal | D473: 0 | E473: 117 | F473: 1 | G473: 57 | H473: TV Movie | I473: Drama | J473: Romance | K473: Unknown | L473: 6 | M473: Hit | N473: 76245 | O473: Low | P473: 38000000 | Q473: 266614059 | R473: 228614059 | S473: Profit | T473: 34065 | U473: Adrian Lyne | V473: 34065 | W473: April | X473: Tuesday | Y473: 1993 | Z473: 6
A474: tt0107290 | B474: Jurassic Park | C474: Jurassic Park | D474: 0 | E474: 127 | F474: 2 | G474: 7 | H474: Long Movie | I474: Action | J474: Adventure | K474: Sci-Fi | L474: 8.2 | M474: Superhit | N474: 1041089 | O474: High | P474: 63000000 | Q474: 1113138548 | R474: 1050138548 | S474: Profit | T474: 34129 | U474: Steven Spielberg | V474: 34129 | W474: June | X474: Wednesday | Y474: 1993 | Z474: 9
A475: tt0107302 | B475: Kalifornia | C475: Kalifornia | D475: 0 | E475: 117 | F475: 1 | G475: 57 | H475: TV Movie | I475: Crime | J475: Drama | K475: Thriller | L475: 6.7 | M475: Hit | N475: 56797 | O475: Low | P475: 9000000 | Q475: 2395231 | R475: -6604769 | S475: Loss | T475: 34182 | U475: Dominic Sena | V475: 34182 | W475: August | X475: Sunday | Y475: 1993 | Z475: 1
A476: tt0107362 | B476: Last Action Hero | C476: Last Action Hero | D476: 0 | E476: 130 | F476: 2 | G476: 10 | H476: Long Movie | I476: Action | J476: Adventure | K476: Comedy | L476: 6.5 | M476: Hit | N476: 160479 | O476: Median | P476: 85000000 | Q476: 137298489 | R476: 52298489 | S476: Profit | T476: 34133 | U476: John McTiernan | V476: 34133 | W476: June | X476: Sunday | Y476: 1993 | Z476: 13
A477: tt0107554 | B477: Menace II Society | C477: Menace II Society | D477: 0 | E477: 97 | F477: 1 | G477: 37 | H477: TV Movie | I477: Crime | J477: Drama | K477: Thriller | L477: 7.5 | M477: Superhit | N477: 63036 | O477: Low | P477: 3500000 | Q477: 27912072 | R477: 24412072 | S477: Profit | T477: 34115 | U477: Albert Hughes, Allen Hughes | V477: 34115 | W477: May | X477: Wednesday | Y477: 1993 | Z477: 26
A478: tt0107614 | B478: Mrs. Doubtfire | C478: Mrs. Doubtfire | D478: 0 | E478: 125 | F478: 2 | G478: 5 | H478: Long Movie | I478: Comedy | J478: Drama | K478: Unknown | L478: 7.1 | M478: Superhit | N478: 283743 | O478: Median | P478: 25000000 | Q478: 441286195 | R478: 416286195 | S478: Profit | T478: 34295 | U478: Chris Columbus | V478: 34295 | W478: November | X478: Monday | Y478: 1993 | Z478: 22
A479: tt0107616 | B479: Much Ado About Nothing | C479: Much Ado About Nothing | D479: 0 | E479: 111 | F479: 1 | G479: 51 | H479: TV Movie | I479: Comedy | J479: Drama | K479: Romance | L479: 7.3 | M479: Superhit | N479: 50854 | O479: Low | P479: 11000000 | Q479: 22549338 | R479: 11549338 | S479: Profit | T479: 34095 | U479: Kenneth Branagh | V479: 34095 | W479: May | X479: Thursday | Y479: 1993 | Z479: 6
... A525: tt0110912 | B525: Pulp Fiction | C525: Pulp Fiction | D525: 0 | E525: 154 | F525: 2 | G525: 34 | H525: Long Movie | I525: Crime | J525: Drama | K525: Unknown | L525: 8.9 | M525: Superhit | N525: 2160463 | O525: Very High | P525: 8000000 | Q525: 213928762 | R525: 205928762 | S525: Profit | T525: 34475 | U525: Quentin Tarantino | V525: 34475 | W525: May | X525: Saturday | Y525: 1994 | Z525: 21
A526: tt0110932 | B526: Quiz Show | C526: Quiz Show | D526: 0 | E526: 133 | F526: 2 | G526: 13 | H526: Long Movie | I526: Biography | J526: Drama | K526: History | L526: 7.5 | M526: Superhit | N526: 72316 | O526: Low | P526: 31000000 | Q526: 24822619 | R526: -6177381 | S526: Loss | T526: NA | U526: Robert Redford | V526: NA | W526: NA | X526: NA | Y526: #VALUE! | Z526: #VALUE!
A527: tt0110950 | B527: Reality Bites | C527: Reality Bites | D527: 0 | E527: 99 | F527: 1 | G527: 39 | H527: TV Movie | I527: Comedy | J527: Drama | K527: Romance | L527: 6.6 | M527: Hit | N527: 52717 | O527: Low | P527: 11500000 | Q527: 33351557 | R527: 21851557 | S527: Profit | T527: 34335 | U527: Ben Stiller | V527: 34335 | W527: January | X527: Saturday | Y527: 1994 | Z527: 1
A528: tt0110989 | B528: Richie Rich | C528: RiÂ¢hie RiÂ¢h | D528: 0 | E528: 95 | F528: 1 | G528: 35 | H528: TV Movie | I528: Comedy | J528: Family | K528: Unknown | L528: 5.4 | M528: Hit | N528: 72205 | O528: Low | P528: 40000000 | Q528: 38087756 | R528: -1912244 | S528: Loss | T528: 34687 | U528: Donald Petrie | V528: 34687 | W528: December | X528: Monday | Y528: 1994 | Z528: 19
A529: tt0111070 | B529: The Santa Clause | C529: The Santa Clause | D529: 0 | E529: 97 | F529: 1 | G529: 37 | H529: TV Movie | I529: Comedy | J529: Drama | K529: Family | L529: 6.5 | M529: Hit | N529: 126968 | O529: Median | P529: 22000000 | Q529: 190539357 | R529: 168539357 | S529: Profit | T529: 34649 | U529: John Pasquin | V529: 34649 | W529: November | X529: Friday | Y529: 1994 | Z529: 11
A530: tt0111149 | B530: Shallow Grave | C530: Shallow Grave | D530: 0 | E530: 89 | F530: 1 | G530: 29 | H530: TV Movie | I530: Crime | J530: Drama | K530: Thriller | L530: 7.3 | M530: Superhit | N530: 65075 | O530: Low | P530: 2500000 | Q530: 2079569 | R530: -420431 | S530: Loss | T530: 34471 | U530: Danny Boyle | V530: 34471 | W530: May | X530: Tuesday | Y530: 1994 | Z530: 17
A531: tt0111161 | B531: The Shawshank Redemption | C531: The Shawshank Redemption | D531: 0 | E531: 142 | F531: 2 | G531: 22 | H531: Long Movie | I531: Drama | J531: Unknown | K531: Unknown | L531: 9.3 | M531: BlockBuster | N531: 2817283 | O531: Very High | P531: 25000000 | Q531: 28884716 | R531: 3884716 | S531: Profit | T531: 34587 | U531: Frank Darabont | V531: 34587 | W531: September | X531: Saturday | Y531: 1994 | Z531: 10
A532: tt0111255 | B532: The Specialist | C532: The Specialist | D532: 0 | E532: 110 | F532: 1 | G532: 50 | H532: TV Movie | I532: Action | J532: Drama | K532: Thriller | L532: 5.6 | M532: Hit | N532: 68821 | O532: Low | P532: 45000000 | Q532: 170362582 | R532: 125362582 | S532: Profit | T532: 34614 | U532: Luis Llosa | V532: 34614 | W532: October | X532: Friday | Y532: 1994 | Z532: 7
A533: tt0111257 | B533: Speed | C533: Speed | D533: 0 | E533: 116 | F533: 1 | G533: 56 | H533: TV Movie | I533: Action | J533: Adventure | K533: Thriller | L533: 7.3 | M533: Superhit | N533: 383702 | O533: Median | P533: 30000000 | Q533: 350448145 | R533: 320448145 | S533: Profit | T533: 34492 | U533: Jan de Bont | V533: 34492 | W533: June | X533: Tuesday | Y533: 1994 | Z533: 7
A534: tt0111280 | B534: Star Trek: Generations | C534: Star Trek: Generations | D534: 0 | E534: 118 | F534: 1 | G534: 58 | H534: TV Movie | I534: Action | J534: Adventure | K534: Mystery | L534: 6.6 | M534: Hit | N534: 85822 | O534: Low | P534: 35000000 | Q534: 118071125 | R534: 83071125 | S534: Profit | T534: 34655 | U534: David Carson | V534: 34655 | W534: November | X534: Thursday | Y534: 1994 | Z534: 17
A535: tt0111282 | B535: Stargate | C535: Stargate | D535: 0 | E535: 116 | F535: 1 | G535: 56 | H535: TV Movie | I535: Action | J535: Adventure | K535: Sci-Fi | L535: 7 | M535: Hit | N535: 200994 | O535: Median | P535: 55000000 | Q535: 196567262 | R535: 141567262 | S535: Profit | T535: 34635 | U535: Roland Emmerich | V535: 34635 | W535: October | X535: Friday | Y535: 1994 | Z535: 28
A536: tt0111301 | B536: Street Fighter | C536: Street Fighter | D536: 0 | E536: 102 | F536: 1 | G536: 42 | H536: TV Movie | I536: Action | J536: Adventure | K536: Comedy | L536: 4 | M536: Average | N536: 74256 | O536: Low | P536: 35000000 | Q536: 99431786 | R536: 64431786 | S536: Profit | T536: 34691 | U536: Steven E. de Souza | V536: 34691 | W536: December | X536: Friday | Y536: 1994 | Z536: 23
A537: tt0111438 | B537: Timecop | C537: Timecop | D537: 0 | E537: 99 | F537: 1 | G537: 39 | H537: TV Movie | I537: Action | J537: Crime | K537: Sci-Fi | L537: 5.9 | M537: Hit | N537: 62760 | O537: Low | P537: 27000000 | Q537: 101646581 | R537: 74646581 | S537: Profit | T537: 34593 | U537: Peter Hyams | V537: 34593 | W537: September | X537: Friday | Y537: 1994 | Z537: 16
...

Sheet EDA
A1: KPI1
B2: TOTAL MOVIES
A3: Count of id
A4: 3348 | B4: =GETPIVOTDATA("id",$A$3) -> 3348
A7: KPI2 | B7: AVERAGE RATING
A9: Average of averageRating
A10: 6.7385305 | B10: =GETPIVOTDATA("averageRating",$A$9) -> 6.7385305
A12: KPI3 | B12: TOTAL BUDGET
A14: Sum of budget
A15: 168715109116 | B15: =GETPIVOTDATA("budget",$A$14) -> 168715109116
A18: KPI4 | B18: TOTAL GROSS REVENUE
A20: Sum of gross
A21: 554423191764 | B21: =GETPIVOTDATA("gross",$A$20) -> 554423191764
A24: KPI5 | B24: TOTAL PROFIT
A26: Sum of Profit
A27: 385708082648 | B27: =GETPIVOTDATA("Profit",$A$26) -> 385708082648
A29: KPI6 | B29: TOTAL DIRECTORES
A31: Count of directors
A32: 3348 | B32: =GETPIVOTDATA("directors",$A$31) -> 3348
A34: KPI7 | B34: HIGHEST RATED MOVIE
B36: Column Labels
B37: Average | C37: BlockBuster | D37: Flop | E37: Hit | F37: Superhit | G37: Grand Total
A38: Count of id | B38: 99 | C38: 2 | D38: 3 | E38: 1954 | F38: 1290 | G38: 3348
B39: =GETPIVOTDATA("id",$A$36,"Movie Type","Average") -> 99 | C39: =GETPIVOTDATA("id",$A$36,"Movie Type","BlockBuster") -> 2 | D39: =GETPIVOTDATA("id",$A$36,"Movie Type","Flop") -> 3 | E39: =GETPIVOTDATA("id",$A$36,"Movie Type","Hit") -> 1954 | F39: =GETPIVOTDATA("id",$A$36,"Movie Type","Superhit") -> 1290 | G39: =GETPIVOTDATA("id",$A$36) -> 3348
A41: KPI8 | B41: HIGHEST GROSSING MOVIE
A43: Max of gross
A44: 2923706026 | B44: =GETPIVOTDATA("gross",$A$43) -> 2923706026
A46: KPI9 | B46: HIGHEST PROFIT MOVIE
A48: Max of Profit
A49: 2686706026 | B49: =GETPIVOTDATA("Profit",$A$48) -> 2686706026
A51: KPI10 | B51: AVERAGE VOTES
A54: Average of numVotes
A55: 215549.24 | B55: =GETPIVOTDATA("numVotes",$A$54) -> 215549.24
A58: EDA 1 | B58: MOVIES RELEASED IN YEAR
A60: Count of id
A61: 3348
A73: EDA2 | B73: MONTH OF THE HIGHEST MOVIE RELEASED
A75: Row Labels | B75: Count of originalTitle
A76: September | B76: 424
A77: June | B77: 358
...

Sheet Dashboard
A1: TOATL MOVIES | C1: AVERAGE RATING | F1: IMDB DASHBOARD | R1: TOTAL REVENUE | U1: TOTAL PROFIT
A2: =EDA!B4 -> 3348 | C2: =EDA!B10 -> 6.7385305 | R2: =EDA!B21 -> 554423191764 | U2: =EDA!B27 -> 385708082648
J3: AVERAGE VOTES
J4: =EDA!B55 -> 215549.24
